2025-10-23 02:47:04,714 - INFO - Processo fonte configurata 'project-overview' (web)
2025-10-23 02:47:04,715 - ERROR - Errore durante la sincronizzazione: Libreria 'requests' non installata. Eseguire 'pip install requests'.
Traceback (most recent call last):
  File "/workspace/Game/scripts/chatgpt_sync.py", line 219, in fetch_from_web
    import requests  # type: ignore
    ^^^^^^^^^^^^^^^
ModuleNotFoundError: No module named 'requests'

The above exception was the direct cause of the following exception:

Traceback (most recent call last):
  File "/workspace/Game/scripts/chatgpt_sync.py", line 648, in main
    process_config(args.config, summary_file=args.summary_file, skip_diff=args.skip_diff)
  File "/workspace/Game/scripts/chatgpt_sync.py", line 606, in process_config
    result = process_single_source(
             ^^^^^^^^^^^^^^^^^^^^^^
  File "/workspace/Game/scripts/chatgpt_sync.py", line 533, in process_single_source
    text, extra_meta = fetch_from_web(
                       ^^^^^^^^^^^^^^^
  File "/workspace/Game/scripts/chatgpt_sync.py", line 221, in fetch_from_web
    raise RuntimeError(
RuntimeError: Libreria 'requests' non installata. Eseguire 'pip install requests'.
2025-10-23 02:47:18,383 - INFO - Processo fonte configurata 'project-overview' (web)
2025-10-23 02:47:18,640 - ERROR - Errore durante la sincronizzazione: HTTPSConnectionPool(host='chatgpt.com', port=443): Max retries exceeded with url: /g/.../project (Caused by ProxyError('Unable to connect to proxy', OSError('Tunnel connection failed: 403 Forbidden')))
Traceback (most recent call last):
  File "/root/.pyenv/versions/3.11.12/lib/python3.11/site-packages/urllib3/connectionpool.py", line 773, in urlopen
    self._prepare_proxy(conn)
  File "/root/.pyenv/versions/3.11.12/lib/python3.11/site-packages/urllib3/connectionpool.py", line 1042, in _prepare_proxy
    conn.connect()
  File "/root/.pyenv/versions/3.11.12/lib/python3.11/site-packages/urllib3/connection.py", line 770, in connect
    self._tunnel()
  File "/root/.pyenv/versions/3.11.12/lib/python3.11/http/client.py", line 943, in _tunnel
    raise OSError(f"Tunnel connection failed: {code} {message.strip()}")
OSError: Tunnel connection failed: 403 Forbidden

The above exception was the direct cause of the following exception:

urllib3.exceptions.ProxyError: ('Unable to connect to proxy', OSError('Tunnel connection failed: 403 Forbidden'))

The above exception was the direct cause of the following exception:

Traceback (most recent call last):
  File "/root/.pyenv/versions/3.11.12/lib/python3.11/site-packages/requests/adapters.py", line 644, in send
    resp = conn.urlopen(
           ^^^^^^^^^^^^^
  File "/root/.pyenv/versions/3.11.12/lib/python3.11/site-packages/urllib3/connectionpool.py", line 841, in urlopen
    retries = retries.increment(
              ^^^^^^^^^^^^^^^^^^
  File "/root/.pyenv/versions/3.11.12/lib/python3.11/site-packages/urllib3/util/retry.py", line 519, in increment
    raise MaxRetryError(_pool, url, reason) from reason  # type: ignore[arg-type]
    ^^^^^^^^^^^^^^^^^^^^^^^^^^^^^^^^^^^^^^^^^^^^^^^^^^^
urllib3.exceptions.MaxRetryError: HTTPSConnectionPool(host='chatgpt.com', port=443): Max retries exceeded with url: /g/.../project (Caused by ProxyError('Unable to connect to proxy', OSError('Tunnel connection failed: 403 Forbidden')))

During handling of the above exception, another exception occurred:

Traceback (most recent call last):
  File "/workspace/Game/scripts/chatgpt_sync.py", line 648, in main
    process_config(args.config, summary_file=args.summary_file, skip_diff=args.skip_diff)
  File "/workspace/Game/scripts/chatgpt_sync.py", line 606, in process_config
    result = process_single_source(
             ^^^^^^^^^^^^^^^^^^^^^^
  File "/workspace/Game/scripts/chatgpt_sync.py", line 533, in process_single_source
    text, extra_meta = fetch_from_web(
                       ^^^^^^^^^^^^^^^
  File "/workspace/Game/scripts/chatgpt_sync.py", line 225, in fetch_from_web
    response = requests.request(
               ^^^^^^^^^^^^^^^^^
  File "/root/.pyenv/versions/3.11.12/lib/python3.11/site-packages/requests/api.py", line 59, in request
    return session.request(method=method, url=url, **kwargs)
           ^^^^^^^^^^^^^^^^^^^^^^^^^^^^^^^^^^^^^^^^^^^^^^^^^
  File "/root/.pyenv/versions/3.11.12/lib/python3.11/site-packages/requests/sessions.py", line 589, in request
    resp = self.send(prep, **send_kwargs)
           ^^^^^^^^^^^^^^^^^^^^^^^^^^^^^^
  File "/root/.pyenv/versions/3.11.12/lib/python3.11/site-packages/requests/sessions.py", line 703, in send
    r = adapter.send(request, **kwargs)
        ^^^^^^^^^^^^^^^^^^^^^^^^^^^^^^^
  File "/root/.pyenv/versions/3.11.12/lib/python3.11/site-packages/requests/adapters.py", line 671, in send
    raise ProxyError(e, request=request)
requests.exceptions.ProxyError: HTTPSConnectionPool(host='chatgpt.com', port=443): Max retries exceeded with url: /g/.../project (Caused by ProxyError('Unable to connect to proxy', OSError('Tunnel connection failed: 403 Forbidden')))
2025-10-23 17:48:39,876 - INFO - Processo fonte configurata 'local-export' (export)
2025-10-23 17:48:39,876 - INFO - Export copiato in data/chatgpt/local/2025-10-23/local-conversation.json
2025-10-23 17:48:39,877 - INFO - Snapshot salvato in data/chatgpt/local/2025-10-23/snapshot-20251023T174839Z-local-export.json
2025-10-23 17:48:39,878 - INFO - Nessuno snapshot precedente trovato per data/chatgpt/local/2025-10-23/snapshot-20251023T174839Z-local-export.json: skip diff
2025-10-23 17:48:39,878 - INFO - Processo fonte configurata 'example-homepage' (web)
2025-10-23 17:48:40,012 - ERROR - Errore durante la sincronizzazione: HTTPSConnectionPool(host='example.com', port=443): Max retries exceeded with url: / (Caused by ProxyError('Unable to connect to proxy', OSError('Tunnel connection failed: 403 Forbidden')))
Traceback (most recent call last):
  File "/root/.pyenv/versions/3.11.12/lib/python3.11/site-packages/urllib3/connectionpool.py", line 773, in urlopen
    self._prepare_proxy(conn)
  File "/root/.pyenv/versions/3.11.12/lib/python3.11/site-packages/urllib3/connectionpool.py", line 1042, in _prepare_proxy
    conn.connect()
  File "/root/.pyenv/versions/3.11.12/lib/python3.11/site-packages/urllib3/connection.py", line 770, in connect
    self._tunnel()
  File "/root/.pyenv/versions/3.11.12/lib/python3.11/http/client.py", line 943, in _tunnel
    raise OSError(f"Tunnel connection failed: {code} {message.strip()}")
OSError: Tunnel connection failed: 403 Forbidden

The above exception was the direct cause of the following exception:

urllib3.exceptions.ProxyError: ('Unable to connect to proxy', OSError('Tunnel connection failed: 403 Forbidden'))

The above exception was the direct cause of the following exception:

Traceback (most recent call last):
  File "/root/.pyenv/versions/3.11.12/lib/python3.11/site-packages/requests/adapters.py", line 644, in send
    resp = conn.urlopen(
           ^^^^^^^^^^^^^
  File "/root/.pyenv/versions/3.11.12/lib/python3.11/site-packages/urllib3/connectionpool.py", line 841, in urlopen
    retries = retries.increment(
              ^^^^^^^^^^^^^^^^^^
  File "/root/.pyenv/versions/3.11.12/lib/python3.11/site-packages/urllib3/util/retry.py", line 519, in increment
    raise MaxRetryError(_pool, url, reason) from reason  # type: ignore[arg-type]
    ^^^^^^^^^^^^^^^^^^^^^^^^^^^^^^^^^^^^^^^^^^^^^^^^^^^
urllib3.exceptions.MaxRetryError: HTTPSConnectionPool(host='example.com', port=443): Max retries exceeded with url: / (Caused by ProxyError('Unable to connect to proxy', OSError('Tunnel connection failed: 403 Forbidden')))

During handling of the above exception, another exception occurred:

Traceback (most recent call last):
  File "/workspace/Game/scripts/chatgpt_sync.py", line 648, in main
    process_config(args.config, summary_file=args.summary_file, skip_diff=args.skip_diff)
  File "/workspace/Game/scripts/chatgpt_sync.py", line 606, in process_config
    result = process_single_source(
             ^^^^^^^^^^^^^^^^^^^^^^
  File "/workspace/Game/scripts/chatgpt_sync.py", line 533, in process_single_source
    text, extra_meta = fetch_from_web(
                       ^^^^^^^^^^^^^^^
  File "/workspace/Game/scripts/chatgpt_sync.py", line 225, in fetch_from_web
    response = requests.request(
               ^^^^^^^^^^^^^^^^^
  File "/root/.pyenv/versions/3.11.12/lib/python3.11/site-packages/requests/api.py", line 59, in request
    return session.request(method=method, url=url, **kwargs)
           ^^^^^^^^^^^^^^^^^^^^^^^^^^^^^^^^^^^^^^^^^^^^^^^^^
  File "/root/.pyenv/versions/3.11.12/lib/python3.11/site-packages/requests/sessions.py", line 589, in request
    resp = self.send(prep, **send_kwargs)
           ^^^^^^^^^^^^^^^^^^^^^^^^^^^^^^
  File "/root/.pyenv/versions/3.11.12/lib/python3.11/site-packages/requests/sessions.py", line 703, in send
    r = adapter.send(request, **kwargs)
        ^^^^^^^^^^^^^^^^^^^^^^^^^^^^^^^
  File "/root/.pyenv/versions/3.11.12/lib/python3.11/site-packages/requests/adapters.py", line 671, in send
    raise ProxyError(e, request=request)
requests.exceptions.ProxyError: HTTPSConnectionPool(host='example.com', port=443): Max retries exceeded with url: / (Caused by ProxyError('Unable to connect to proxy', OSError('Tunnel connection failed: 403 Forbidden')))
2025-10-23 17:48:52,595 - INFO - Processo fonte configurata 'local-export' (export)
2025-10-23 17:48:52,595 - INFO - Export copiato in data/chatgpt/local/2025-10-23/local-conversation-1.json
2025-10-23 17:48:52,596 - INFO - Snapshot salvato in data/chatgpt/local/2025-10-23/snapshot-20251023T174852Z-local-export.json
2025-10-23 17:48:52,597 - INFO - Diff scritto in docs/chatgpt_changes/local/2025-10-23/snapshot-20251023T174852Z-local-export.diff
2025-10-23 17:48:52,597 - INFO - Processo fonte configurata 'local-notes' (export)
2025-10-23 17:48:52,598 - INFO - Export copiato in data/chatgpt/notes/2025-10-23/notes-conversation.json
2025-10-23 17:48:52,598 - INFO - Snapshot salvato in data/chatgpt/notes/2025-10-23/snapshot-20251023T174852Z-daily-notes.json
2025-10-23 17:48:52,598 - INFO - Nessuno snapshot precedente trovato per data/chatgpt/notes/2025-10-23/snapshot-20251023T174852Z-daily-notes.json: skip diff
2025-10-23 17:48:52,599 - INFO - Riepilogo scritto in logs/chatgpt_sync_last.json
2025-10-23 23:12:30,100 - INFO - Processo fonte configurata 'local-export' (export)
2025-10-23 23:12:30,101 - ERROR - Errore durante la sincronizzazione: File di export non trovato: /workspace/Game/data/data/exports/local-conversation.json
Traceback (most recent call last):
  File "/workspace/Game/scripts/chatgpt_sync.py", line 648, in main
    process_config(args.config, summary_file=args.summary_file, skip_diff=args.skip_diff)
  File "/workspace/Game/scripts/chatgpt_sync.py", line 606, in process_config
    result = process_single_source(
             ^^^^^^^^^^^^^^^^^^^^^^
  File "/workspace/Game/scripts/chatgpt_sync.py", line 517, in process_single_source
    snapshot_info = import_export(export_file, namespace=namespace_slug)
                    ^^^^^^^^^^^^^^^^^^^^^^^^^^^^^^^^^^^^^^^^^^^^^^^^^^^^
  File "/workspace/Game/scripts/chatgpt_sync.py", line 189, in import_export
    copied_path = copy_export_file(export_file, namespace=namespace)
                  ^^^^^^^^^^^^^^^^^^^^^^^^^^^^^^^^^^^^^^^^^^^^^^^^^^
  File "/workspace/Game/scripts/chatgpt_sync.py", line 130, in copy_export_file
    raise FileNotFoundError(f"File di export non trovato: {source}")
FileNotFoundError: File di export non trovato: /workspace/Game/data/data/exports/local-conversation.json
2025-10-23 23:12:41,804 - INFO - Processo fonte configurata 'local-export' (export)
2025-10-23 23:12:41,806 - INFO - Export copiato in data/chatgpt/local/2025-10-23/local-conversation-2.json
2025-10-23 23:12:41,808 - INFO - Snapshot salvato in data/chatgpt/local/2025-10-23/snapshot-20251023T231241Z-local-export.json
2025-10-23 23:12:41,810 - INFO - Diff scritto in docs/chatgpt_changes/local/2025-10-23/snapshot-20251023T231241Z-local-export.diff
2025-10-23 23:12:41,811 - INFO - Processo fonte configurata 'local-notes' (export)
2025-10-23 23:12:41,812 - INFO - Export copiato in data/chatgpt/notes/2025-10-23/notes-conversation-1.json
2025-10-23 23:12:41,813 - INFO - Snapshot salvato in data/chatgpt/notes/2025-10-23/snapshot-20251023T231241Z-daily-notes.json
2025-10-23 23:12:41,815 - INFO - Diff scritto in docs/chatgpt_changes/notes/2025-10-23/snapshot-20251023T231241Z-daily-notes.diff
2025-10-23 23:12:41,816 - INFO - Riepilogo scritto in logs/chatgpt_sync_last.json
2025-10-24 02:10:01,973 - INFO - Processo fonte configurata 'local-export' (export)
2025-10-24 02:10:01,974 - INFO - Export copiato in data/chatgpt/local/2025-10-24/local-conversation.json
2025-10-24 02:10:01,975 - INFO - Snapshot salvato in data/chatgpt/local/2025-10-24/snapshot-20251024T021001Z-local-export.json
2025-10-24 02:10:01,978 - INFO - Diff scritto in docs/chatgpt_changes/local/2025-10-24/snapshot-20251024T021001Z-local-export.diff
2025-10-24 02:10:01,978 - INFO - Processo fonte configurata 'local-notes' (export)
2025-10-24 02:10:01,979 - INFO - Export copiato in data/chatgpt/notes/2025-10-24/notes-conversation.json
2025-10-24 02:10:01,980 - INFO - Snapshot salvato in data/chatgpt/notes/2025-10-24/snapshot-20251024T021001Z-daily-notes.json
2025-10-24 02:10:01,983 - INFO - Diff scritto in docs/chatgpt_changes/notes/2025-10-24/snapshot-20251024T021001Z-daily-notes.diff
2025-10-24 02:10:01,984 - INFO - Riepilogo scritto in logs/chatgpt_sync_last.json
2025-10-24 02:19:02,765 - INFO - Processo fonte configurata 'local-export' (export)
2025-10-24 02:19:02,766 - INFO - Export copiato in data/chatgpt/local/2025-10-24/local-conversation-1.json
2025-10-24 02:19:02,767 - INFO - Snapshot salvato in data/chatgpt/local/2025-10-24/snapshot-20251024T021902Z-local-export.json
2025-10-24 02:19:02,769 - INFO - Diff scritto in docs/chatgpt_changes/local/2025-10-24/snapshot-20251024T021902Z-local-export.diff
2025-10-24 02:19:02,769 - INFO - Processo fonte configurata 'local-notes' (export)
2025-10-24 02:19:02,769 - INFO - Export copiato in data/chatgpt/notes/2025-10-24/notes-conversation-1.json
2025-10-24 02:19:02,770 - INFO - Snapshot salvato in data/chatgpt/notes/2025-10-24/snapshot-20251024T021902Z-daily-notes.json
2025-10-24 02:19:02,771 - INFO - Diff scritto in docs/chatgpt_changes/notes/2025-10-24/snapshot-20251024T021902Z-daily-notes.diff
2025-10-24 02:19:02,771 - INFO - Riepilogo scritto in logs/chatgpt_sync_last.json
